{
 "PRed": [
  {
   "PR": {
    "__lazy_json__": "pr_json/2bc8ad4c-e89c-4beb-9448-8837e1eb7167.json"
   },
   "data": {
    "bot_rerun": false,
    "migrator_name": "MigrationYaml",
    "migrator_object_version": 1,
    "migrator_version": 0,
    "name": "python310"
   },
   "keys": [
    "bot_rerun",
    "migrator_name",
    "migrator_object_version",
    "migrator_version",
    "name"
   ]
  },
  {
   "PR": {
    "__lazy_json__": "pr_json/801761996.json"
   },
   "data": {
    "bot_rerun": false,
    "migrator_name": "Version",
    "migrator_version": 0,
    "version": "2.0.1"
   },
   "keys": [
    "bot_rerun",
    "migrator_name",
    "migrator_version",
    "version"
   ]
  },
  {
   "PR": {
    "__lazy_json__": "pr_json/832598048.json"
   },
   "data": {
    "bot_rerun": false,
    "migrator_name": "Version",
    "migrator_version": 0,
    "version": "2.0.2"
   },
   "keys": [
    "bot_rerun",
    "migrator_name",
    "migrator_version",
    "version"
   ]
  }
 ],
 "bad": false,
 "pinning_version": "2022.01.26.09.22.36",
 "pre_pr_migrator_attempts": {
  "pypy38": 5,
  "python311": 461
 },
 "pre_pr_migrator_status": {
  "pypy38": "bot error (<a href=\"https://github.com/regro/autotick-bot/actions/runs/3954382363\">bot CI job</a>): main: Traceback (most recent call last):\n  File \"/home/runner/work/autotick-bot/autotick-bot/cf-scripts/conda_forge_tick/auto_tick.py\", line 1166, in _run_migrator\n    migrator_uid, pr_json = run(\n  File \"/home/runner/work/autotick-bot/autotick-bot/cf-scripts/conda_forge_tick/auto_tick.py\", line 279, in run\n    eval_cmd(\n  File \"/home/runner/work/autotick-bot/autotick-bot/cf-scripts/conda_forge_tick/utils.py\", line 340, in eval_cmd\n    c.check_returncode()\n  File \"/usr/share/miniconda3/envs/run_env/lib/python3.9/subprocess.py\", line 460, in check_returncode\n    raise CalledProcessError(self.returncode, self.args, self.stdout,\nsubprocess.CalledProcessError: Command 'conda smithy rerender -c auto --no-check-uptodate' returned non-zero exit status 1.\n",
  "python311": "bot error (<a href=\"https://github.com/regro/cf-scripts/actions/runs/4873132896\">bot CI job</a>): main: Traceback (most recent call last):\n  File \"/home/runner/work/cf-scripts/cf-scripts/cf-scripts/conda_forge_tick/auto_tick.py\", line 1186, in _run_migrator\n    migrator_uid, pr_json = run(\n  File \"/home/runner/work/cf-scripts/cf-scripts/cf-scripts/conda_forge_tick/auto_tick.py\", line 282, in run\n    eval_cmd(\n  File \"/home/runner/work/cf-scripts/cf-scripts/cf-scripts/conda_forge_tick/utils.py\", line 341, in eval_cmd\n    c.check_returncode()\n  File \"/usr/share/miniconda3/envs/cf-scripts/lib/python3.9/subprocess.py\", line 460, in check_returncode\n    raise CalledProcessError(self.returncode, self.args, self.stdout,\nsubprocess.CalledProcessError: Command 'conda smithy rerender -c auto --no-check-uptodate' returned non-zero exit status 1.\n"
 },
 "smithy_version": "3.16.2"
}