{
 "PRed": [
  {
   "PR": {
    "number": 1,
    "state": "closed"
   },
   "data": {
    "bot_rerun": false,
    "migrator_name": "CompilerRebuild",
    "migrator_version": 1,
    "name": "Python 3.7, GCC 7, R 3.5.1, openBLAS 0.3.2"
   },
   "keys": [
    "bot_rerun",
    "migrator_name",
    "migrator_version",
    "name"
   ]
  },
  {
   "PR": {
    "__lazy_json__": "pr_json/336161169.json"
   },
   "data": {
    "bot_rerun": false,
    "migrator_name": "MigrationYaml",
    "migrator_object_version": 1,
    "migrator_version": 0,
    "name": "python38"
   },
   "keys": [
    "bot_rerun",
    "migrator_name",
    "migrator_object_version",
    "migrator_version",
    "name"
   ]
  },
  {
   "PR": {
    "number": 4,
    "state": "closed"
   },
   "data": {
    "bot_rerun": 1600812301.8135285,
    "migrator_name": "MigrationYaml",
    "migrator_object_version": 1,
    "migrator_version": 0,
    "name": "pypy"
   },
   "keys": [
    "bot_rerun",
    "migrator_name",
    "migrator_object_version",
    "migrator_version",
    "name"
   ]
  },
  {
   "PR": {
    "__lazy_json__": "pr_json/492047520.json"
   },
   "data": {
    "bot_rerun": false,
    "migrator_name": "MigrationYaml",
    "migrator_object_version": 1,
    "migrator_version": 0,
    "name": "pypy"
   },
   "keys": [
    "bot_rerun",
    "migrator_name",
    "migrator_object_version",
    "migrator_version",
    "name"
   ]
  },
  {
   "PR": {
    "__lazy_json__": "pr_json/502064618.json"
   },
   "data": {
    "bot_rerun": false,
    "migrator_name": "MigrationYaml",
    "migrator_object_version": 2,
    "migrator_version": 0,
    "name": "python39"
   },
   "keys": [
    "bot_rerun",
    "migrator_name",
    "migrator_object_version",
    "migrator_version",
    "name"
   ]
  },
  {
   "PR": {
    "__lazy_json__": "pr_json/585832003.json"
   },
   "data": {
    "bot_rerun": false,
    "migrator_name": "MigrationYaml",
    "migrator_object_version": 1,
    "migrator_version": 0,
    "name": "pypy37"
   },
   "keys": [
    "bot_rerun",
    "migrator_name",
    "migrator_object_version",
    "migrator_version",
    "name"
   ]
  },
  {
   "PR": {
    "__lazy_json__": "pr_json/831787170.json"
   },
   "data": {
    "bot_rerun": false,
    "migrator_name": "MigrationYaml",
    "migrator_object_version": 1,
    "migrator_version": 0,
    "name": "python310"
   },
   "keys": [
    "bot_rerun",
    "migrator_name",
    "migrator_object_version",
    "migrator_version",
    "name"
   ]
  }
 ],
 "bad": {
  "exception": "ac-k3atodu-shard-00-01.mvdqvie.mongodb.net:27017: connection closed",
  "traceback": [
   "Traceback (most recent call last):",
   "  File \"/home/runner/micromamba/envs/cf-scripts/lib/python3.10/site-packages/pymongo/pool.py\", line 932, in command",
   "    return command(",
   "  File \"/home/runner/micromamba/envs/cf-scripts/lib/python3.10/site-packages/pymongo/network.py\", line 181, in command",
   "    reply = receive_message(conn, request_id)",
   "  File \"/home/runner/micromamba/envs/cf-scripts/lib/python3.10/site-packages/pymongo/network.py\", line 247, in receive_message",
   "    length, _, response_to, op_code = _UNPACK_HEADER(_receive_data_on_socket(conn, 16, deadline))",
   "  File \"/home/runner/micromamba/envs/cf-scripts/lib/python3.10/site-packages/pymongo/network.py\", line 336, in _receive_data_on_socket",
   "    raise OSError(\"connection closed\")",
   "OSError: connection closed",
   "",
   "The above exception was the direct cause of the following exception:",
   "",
   "Traceback (most recent call last):",
   "  File \"/home/runner/work/cf-scripts/cf-scripts/cf-scripts/conda_forge_tick/auto_tick.py\", line 1257, in _run_migrator",
   "    migrator_uid, pr_json = run(",
   "  File \"/home/runner/work/cf-scripts/cf-scripts/cf-scripts/conda_forge_tick/auto_tick.py\", line 383, in run",
   "    _set_pre_pr_migrator_fields(",
   "  File \"/home/runner/work/cf-scripts/cf-scripts/cf-scripts/conda_forge_tick/auto_tick.py\", line 144, in _set_pre_pr_migrator_fields",
   "    with attrs[\"pr_info\"] as pri:",
   "  File \"/home/runner/work/cf-scripts/cf-scripts/cf-scripts/conda_forge_tick/lazy_json_backends.py\", line 655, in __exit__",
   "    self._dump(purge=True)",
   "  File \"/home/runner/work/cf-scripts/cf-scripts/cf-scripts/conda_forge_tick/lazy_json_backends.py\", line 625, in _dump",
   "    backend.hset(self.hashmap, self.node, data_str)",
   "  File \"/home/runner/work/cf-scripts/cf-scripts/cf-scripts/conda_forge_tick/lazy_json_backends.py\", line 246, in hset",
   "    coll.update_one(",
   "  File \"/home/runner/micromamba/envs/cf-scripts/lib/python3.10/site-packages/pymongo/collection.py\", line 1088, in update_one",
   "    self._update_retryable(",
   "  File \"/home/runner/micromamba/envs/cf-scripts/lib/python3.10/site-packages/pymongo/collection.py\", line 883, in _update_retryable",
   "    return self.__database.client._retryable_write(",
   "  File \"/home/runner/micromamba/envs/cf-scripts/lib/python3.10/site-packages/pymongo/mongo_client.py\", line 1568, in _retryable_write",
   "    return self._retry_with_session(retryable, func, s, None)",
   "  File \"/home/runner/micromamba/envs/cf-scripts/lib/python3.10/site-packages/pymongo/mongo_client.py\", line 1413, in _retry_with_session",
   "    return self._retry_internal(retryable, func, session, bulk)",
   "  File \"/home/runner/micromamba/envs/cf-scripts/lib/python3.10/site-packages/pymongo/_csot.py\", line 108, in csot_wrapper",
   "    return func(self, *args, **kwargs)",
   "  File \"/home/runner/micromamba/envs/cf-scripts/lib/python3.10/site-packages/pymongo/mongo_client.py\", line 1467, in _retry_internal",
   "    raise last_error",
   "  File \"/home/runner/micromamba/envs/cf-scripts/lib/python3.10/site-packages/pymongo/mongo_client.py\", line 1460, in _retry_internal",
   "    return func(session, conn, retryable)",
   "  File \"/home/runner/micromamba/envs/cf-scripts/lib/python3.10/site-packages/pymongo/collection.py\", line 864, in _update",
   "    return self._update(",
   "  File \"/home/runner/micromamba/envs/cf-scripts/lib/python3.10/site-packages/pymongo/collection.py\", line 818, in _update",
   "    result = conn.command(",
   "  File \"/home/runner/micromamba/envs/cf-scripts/lib/python3.10/site-packages/pymongo/helpers.py\", line 315, in inner",
   "    return func(*args, **kwargs)",
   "  File \"/home/runner/micromamba/envs/cf-scripts/lib/python3.10/site-packages/pymongo/pool.py\", line 960, in command",
   "    self._raise_connection_failure(error)",
   "  File \"/home/runner/micromamba/envs/cf-scripts/lib/python3.10/site-packages/pymongo/pool.py\", line 1134, in _raise_connection_failure",
   "    _raise_connection_failure(self.address, error)",
   "  File \"/home/runner/micromamba/envs/cf-scripts/lib/python3.10/site-packages/pymongo/pool.py\", line 406, in _raise_connection_failure",
   "    raise AutoReconnect(msg) from error",
   "pymongo.errors.AutoReconnect: ac-k3atodu-shard-00-01.mvdqvie.mongodb.net:27017: connection closed",
   ""
  ]
 },
 "pinning_version": "2022.01.25.13.00.06",
 "pre_pr_migrator_attempts": {
  "pypy37": 1,
  "pypy38": 434,
  "python311": 827
 },
 "pre_pr_migrator_status": {
  "pypy37": "not solvable (<a href=\"https://github.com/regro/autotick-bot/actions/runs/624978124\">bot CI job</a>): master: ['linux_64_python3.7.____73_pypy: Encountered problems while solving.\\nProblem: package h2-2.6.2-py27_0 has constraint python_abi * *_cp27mu conflicting with python_abi-3.7-1_pypy37_pp73\\n', 'linux_64_python3.8.____cpython: Encountered problems while solving.\\nProblem: package h2-2.6.2-py27_0 requires hyperframe >=5.1.0,<6, but none of the providers can be installed\\n', 'osx_64_python3.7.____73_pypy: Encountered problems while solving.\\nProblem: package h2-2.6.2-py27_0 has constraint python_abi * *_cp27m conflicting with python_abi-3.7-1_pypy37_pp73\\n', 'osx_64_python3.8.____cpython: Encountered problems while solving.\\nProblem: package h2-2.6.2-py27_0 requires hyperframe >=5.1.0,<6, but none of the providers can be installed\\n', 'win_64_python3.8.____cpython: Encountered problems while solving.\\nProblem: package h2-2.6.2-py27_0 requires hyperframe >=5.1.0,<6, but none of the providers can be installed\\n']",
  "pypy38": "not solvable (<a href=\"https://github.com/regro/cf-scripts/actions/runs/5984219765\">bot CI job</a>): main: ['linux_64_python3.10.____cpython: Encountered problems while solving:\\n  - package h2-2.6.2-py27_0 requires hyperframe >=5.1.0,<6, but none of the providers can be installed\\n', 'linux_64_python3.8.____73_pypy: Encountered problems while solving:\\n  - package h2-2.6.2-py27_0 requires hyperframe >=5.1.0,<6, but none of the providers can be installed\\n', 'linux_64_python3.8.____cpython: Encountered problems while solving:\\n  - package h2-2.6.2-py27_0 requires hyperframe >=5.1.0,<6, but none of the providers can be installed\\n', 'linux_64_python3.9.____73_pypy: Encountered problems while solving:\\n  - package h2-2.6.2-py27_1 requires python 2.7*, but none of the providers can be installed\\n', 'linux_64_python3.9.____cpython: Encountered problems while solving:\\n  - package h2-2.6.2-py27_0 requires hyperframe >=5.1.0,<6, but none of the providers can be installed\\n', 'osx_64_python3.10.____cpython: Encountered problems while solving:\\n  - package h2-2.6.2-py27_0 requires hyperframe >=5.1.0,<6, but none of the providers can be installed\\n', 'osx_64_python3.8.____73_pypy: Encountered problems while solving:\\n  - package h2-2.6.2-py27_0 requires hyperframe >=5.1.0,<6, but none of the providers can be installed\\n', 'osx_64_python3.8.____cpython: Encountered problems while solving:\\n  - package h2-2.6.2-py27_0 requires hyperframe >=5.1.0,<6, but none of the providers can be installed\\n', 'osx_64_python3.9.____73_pypy: Encountered problems while solving:\\n  - package h2-2.6.2-py27_1 requires python 2.7*, but none of the providers can be installed\\n', 'osx_64_python3.9.____cpython: Encountered problems while solving:\\n  - package h2-2.6.2-py27_0 requires hyperframe >=5.1.0,<6, but none of the providers can be installed\\n', 'win_64_python3.10.____cpython: Encountered problems while solving:\\n  - nothing provides vc 9.* needed by python-2.7.12-0\\n', 'win_64_python3.8.____73_pypy: Encountered problems while solving:\\n  - nothing provides vc 9.* needed by python-2.7.12-0\\n', 'win_64_python3.8.____cpython: Encountered problems while solving:\\n  - nothing provides vc 9.* needed by python-2.7.12-0\\n', 'win_64_python3.9.____73_pypy: Encountered problems while solving:\\n  - nothing provides vc 9.* needed by python-2.7.12-0\\n', 'win_64_python3.9.____cpython: Encountered problems while solving:\\n  - nothing provides vc 9.* needed by python-2.7.12-0\\n']",
  "python311": "not solvable (<a href=\"https://github.com/regro/cf-scripts/actions/runs/6017854564\">bot CI job</a>): main: ['linux_64_python3.10.____cpython: Encountered problems while solving:\\n  - package python-3.10.8-0_native230_graalpy requires python_abi 3.10.* *_graalpy230_310_native, but none of the providers can be installed\\n', 'linux_64_python3.11.____cpython: Encountered problems while solving:\\n  - package h2-2.6.2-py27_0 requires hyperframe >=5.1.0,<6, but none of the providers can be installed\\n', 'linux_64_python3.8.____cpython: Encountered problems while solving:\\n  - package h2-2.6.2-py27_0 requires hyperframe >=5.1.0,<6, but none of the providers can be installed\\n', 'linux_64_python3.9.____cpython: Encountered problems while solving:\\n  - package h2-2.6.2-py27_1 requires python 2.7*, but none of the providers can be installed\\n', 'osx_64_python3.10.____cpython: Encountered problems while solving:\\n  - package h2-2.6.2-py27_1 requires python 2.7*, but none of the providers can be installed\\n', 'osx_64_python3.11.____cpython: Encountered problems while solving:\\n  - package h2-2.6.2-py27_0 requires hyperframe >=5.1.0,<6, but none of the providers can be installed\\n', 'osx_64_python3.8.____cpython: Encountered problems while solving:\\n  - package h2-2.6.2-py27_0 requires hyperframe >=5.1.0,<6, but none of the providers can be installed\\n', 'osx_64_python3.9.____cpython: Encountered problems while solving:\\n  - package h2-2.6.2-py27_1 requires python 2.7*, but none of the providers can be installed\\n', 'win_64_python3.10.____cpython: Encountered problems while solving:\\n  - nothing provides vc 9.* needed by python-2.7.12-0\\n', 'win_64_python3.11.____cpython: Encountered problems while solving:\\n  - nothing provides vc 9.* needed by python-2.7.12-0\\n', 'win_64_python3.8.____cpython: Encountered problems while solving:\\n  - nothing provides vc 9.* needed by python-2.7.12-0\\n', 'win_64_python3.9.____cpython: Encountered problems while solving:\\n  - nothing provides vc 9.* needed by python-2.7.12-0\\n']"
 },
 "smithy_version": "3.16.1"
}